Workbook

Sheet Matriz Ckeck LIst
C3: MATRIZ PARA COMPROBACIÓN REQUERIMIENTOS DE CALIDAD DE PROYECTO ACADEMICO
D5: SISTEMA: | E5: SISTEMA DE INSCRIPCIÓN DE CURSOS (SIC)
F6: Requerimientos Funcionales
B7: Nº | C7: CRITERIOS DE CALIDAD (Documento/Requerimientos) | E7: Status Nivel de Acuerdo | F7: CU-01 Acceder al sistema | G7: Status Nivel de Acuerdo | H7: 100 | I7: CU - 02 Gestionar perfiles | J7: Status Nivel de Acuerdo | K7: CU - 03 Gestionar Docentes | L7: Status Nivel de Acuerdo | M7: CU - 04 Gestionar cursos | N7: Status Nivel de Acuerdo | O7: CU - 05 Completar inscripción en línea | P7: Status Nivel de Acuerdo | Q7: CU - 06 Gestionar becas | R7: Status Nivel de Acuerdo | S7: CU - 07 Consultar reportes académicos | T7: Status Nivel de Acuerdo | U7: CU - 08 Consultar reportes financieros | V7: Status Nivel de Acuerdo | W7: CU - 09 Gestionar auditoría | X7: Status Nivel de Acuerdo | Y7: CU - 10 Gestionar notificaciones
H8: 0
B9: 1 | C9: Agreed | E9: OK | F9: 1. Minutas de entrevistas al departamento de TICS y jefe académico. 2. Audios de entrevistas al departamento de TICS y jefe académico. | G9: OK | H9: 1 | I9: 1. Minutas de entrevistas al departamento de TICS y jefe académico. 2. Audios de entrevistas al departamento de TICS y jefe académico. | J9: OK | K9: 1. Minutas de entrevistas al departamento de TICS y jefe académico. 2. Audios de entrevistas al departamento de TICS y jefe académico. | L9: OK | M9: 1. Minutas de entrevistas al departamento de TICS y jefe académico. 2. Audios de entrevistas al departamento de TICS y jefe académico. 3. Consenso institucional sobre las reglas de apertura de cursos (mínimo 10 participantes), modalidades y causas de reprogramación | N9: OK | O9: 1. Minutas de entrevistas al departamento de TICS y jefe académico. 2. Audios de entrevistas al departamento de TICS y jefe académico. 3.Interfaces revisadas y validadas mediante reuniones asincrónicas entre el jefe de TICS y jefe académico. | P9: OK | Q9: 1. Minuta de la entrevista. 2. Audio de la entrevista. | R9: OK | S9: 1. Minutas de entrevistas al departamento de TICS y jefe académico. 2. Audios de entrevistas al departamento de TICS y jefe académico. | T9: OK | U9: 1. Minutas de entrevistas al departamento de TICS y jefe académico. 2. Audios de entrevistas al departamento de TICS y jefe académico. 3.Interfaces revisadas y validadas mediante reuniones asincrónicas entre el jefe de TICS y jefe académico. | V9: OK | W9: 1. Minuta de la entrevista. 2. Audio de la entrevista. | X9: OK | Y9: 1. Minutas de entrevistas al departamento de TICS y jefe académico. 2. Audios de entrevistas al departamento de TICS y jefe académico.
B10: 2 | C10: Ranked | E10: OK | F10: 1. Los requisitos asociados tienen prioridad definida mediante la técnica MoSCoW. 2. Clasificación "Must have" para Iniciar sesión (RF-04) y Cambiar contraseña (RF-05). 3.Clasificación "Should have" para Recuperar contraseña (RF-27) | G10: OK | I10: 1.Los requisitos asociados tienen prioridad definida mediante la técnica MoSCoW. 2.Clasificación "Must have" para Crear perfil (RF-01), Registrar usuario (RF-02) y Asignar usuario a perfil (RF-03). 3.Clasificación "Should have" para Modificar perfil (RF-28), Consultar perfiles (RF-29) y Desactivar acceso (RF-31). | J10: OK | K10: 1. Los requisitos asociados al CU-03 tienen su prioridad definida como Must have mediante MoSCoW. | L10: OK | M10: 1. Los requisitos asociados tienen prioridad definida mediante la técnica MoSCoW. 2. Clasificación "Must have" para la creación académica, condiciones de inscripción y asignación de docentes (RF-08, RF-09 y RF-10). 3.Clasificación "Must have" para la modificación y reprogramación de cursos publicados (RF-11 a RF-14) | N10: OK | O10: 1.Los requisitos asociados tienen prioridad definida mediante la técnica MoSCoW. 2.Clasificación "Must have" para Completar inscripción en línea (RF-18), Subir comprobante de pago (RF-19), Generar comprobante de inscripción (RF-20) y Consultar estado de inscripción (RF-21). 3.En este caso de uso todos los requisitos son considerados indispensables para el sistema, por lo que no existen clasificaciones "Should have" o "Could have". | P10: OK | Q10: 1. Requisitos jerarquizados con la técnica MoSCoW y definidos como Must Have (RF-15, RF-16 y RF-17) y como Should Have (RF-33, RF-34, RF-35 y RF-39) | R10: OK | S10: 1. Los requisitos asociados tienen prioridad definida mediante la técnica MoSCoW. 2. Clasificación "Must have" para la consulta de inscritos por curso (RF-22). 3.Clasificación "Should have" para las consultas de beneficiarios de beca, media beca, cursos habilitados y filtros combinados (RF-34, RF-35, RF-36 y RF-40) | T10: OK | U10: 1. Los requisitos asociados tienen prioridad definida mediante la técnica MoSCoW. 2. Clasificación "Must have" para la consulta de participantes con pago registrado (RF-23), pago pendiente (RF-24) y pagos por curso (RF-25). 3. Clasificación "Should have" para el filtrado por curso o periodo (RF-40) | V10: OK | W10: 1. Requisitos jerarquizados con la técnica MoSCoW y definidos como Should Have (RF-42) y como Could Have (RF-44, RF-45 y RF-46). | X10: OK | Y10: 1. Los requisitos asociados tienen prioridad definida mediante la técnica MoSCoW. 2. Clasificación "Must have" para la notificación de reprogramaciones de cursos (RF-26). 3.Clasificación "Should have" para las notificaciones de creación, actualización y resultados de beca (RF-37, RF-38 y RF-39contraseña (RF-27)
B11: 3 | C11: Unambiguos | E11: OK | F11: 1. La descripción del caso de uso utiliza lenguaje claro. 2. Se especifican actores, flujo, excepciones y criterios de aceptación. | G11: OK | I11: 1. Redacción en lenguaje claro. 2. El equipo interpretan de igual manera el caso de uso | J11: OK | K11: 1. La descripción del CU-03 utiliza lenguaje claro. 2. Se especifica el actor y las funciones que puede realizar. | L11: OK | M11: 1. La descripción del caso de uso utiliza lenguaje claro. 2.Detalle explícito de campos de entrada, tipos de datos, validaciones y tratamiento de excepciones paso a paso 3. Formulación de criterios de aceptación estructurados bajo la sintaxis Dado-Cuando-Entonces | N11: OK | O11: 1. Redacción en lenguaje claro. 2. El equipo interpretan de igual manera el caso de uso | P11: OK | Q11: 1. Redacción formal y estructurada (SRS). 2. Definición de precondiciones, entradas obligatorias, flujos principales, flujos alternativos y criterios de aceptación. | R11: OK | S11: 1. La descripción del caso de uso utiliza lenguaje claro. 2. Se especifican actores, flujo, excepciones y criterios de aceptación. | T11: OK | U11: 1. Redacción formal y en lenguaje claro. 2. Se definen explícitamente los campos, estados de pago (Aprobado, Pendiente de validación) y fórmulas contables según FMT-09 y FMT-12. 3. Especificación detallada de flujos, excepciones y criterios de aceptación. | V11: OK | W11: 1. Lenguaje claro y formal. 2. Captura automática de metadatos y reglas de inmutabilidad. | X11: OK | Y11: 1. La descripción del caso de uso utiliza lenguaje claro. 2. Se especifican actores, flujo, excepciones y criterios de aceptación.
B12: 4 | C12: Valid and up-to date | E12: OK | F12: 1. Toda nueva información ha sido incorporada, se han incorporado los últimos cambios pedidos luego del feedback realizado por el cliente | G12: OK | I12: 1. Se han incorporado los últimos cambios pedidos luego del feedback realizado por el cliente | J12: OK | K12: 1. Se han incorporado los últimos cambios cambios tras el feedback realizado por el cliente | L12: OK | M12: 1. Toda nueva información ha sido incorporada, se han incorporado los últimos cambios pedidos luego del feedback realizado por el cliente | N12: OK | O12: 1. Se han incorporado los últimos cambios pedidos luego del feedback realizado por el cliente | P12: OK | Q12: 1. Proceso real de selección del CEPEIGE para cursos panamericanos. 2. Observaciones del cliente sobre la importación de archivos CSV de beneficiarios. | R12: OK | S12: 1. Toda nueva información ha sido incorporada, se han incorporado los últimos cambios pedidos luego del feedback realizado por el cliente | T12: OK | U12: 1. Se han incorporado los últimos cambios pedidos luego del feedback realizado por el cliente. 2. Refleja los requerimientos financieros actuales para el control de ingresos y saldos de cursos del CEPEIGE. | V12: OK | W12: 1. Responde a la necesidad institucional de controlar accesos no autorizados. 2. Aseguramiento del cálculo de trazabilidad. | X12: OK | Y12: 1. Toda nueva información ha sido incorporada, se han incorporado los últimos cambios pedidos luego del feedback realizado por el cliente
B13: 5 | C13: Correct | E13: OK | F13: 1. Está alineado con los objetivos del sistema. 2. Refleja lo que realmente necesita el cliente. | G13: OK | I13: 1. Está alineado con los objetivos del sistema. 2. Refleja lo que realmente necesita el cliente. | J13: OK | K13: 1. Está alineado con los objetivos del sistema. 2. Refleja lo que realmente necesita el cliente. | L13: OK | M13: 1. Está alineado con los objetivos del sistema. 2. Cobertura de las necesidades reales de gestión para cursos presenciales, virtuales e híbridos | N13: OK | O13: 1. Está alineado con los objetivos del sistema. 2. Refleja lo que realmente necesita el cliente. | P13: OK | Q13: 1. Alineado con el objetivo del sistema. 2. Resuelve la problemática actual de la dispersión de archivos Excel y formularios independientes. | R13: OK | S13: 1. Está alineado con los objetivos del sistema. 2. Refleja lo que realmente necesita el cliente. | T13: OK | U13: 1. Está alineado con los objetivos del sistema. 2. Refleja lo que realmente necesita el Jefe Financiero para la validación y consolidación de pagos | V13: OK | W13: 1. Alineado con el Módulo 7: Gestión de Auditoría del sistema SIC y con la Ley Orgánica de Protección de Datos Personales del Ecuador. | X13: OK | Y13: 1. Está alineado con los objetivos del sistema. 2. Refleja lo que realmente necesita el cliente.
B14: 6 | C14: Consisten | E14: OK | F14: 1. Documentación basada en modelos: Diagrama de Casos de Uso 2. Usa términos definidos previamente, considerando acrónimos y abreviaturas. 3. Ausencia de contradicciones entre las condiciones del flujo principal y los criterios de aceptación. | G14: OK | I14: 1. Documentación basada en modelos: Diagrama de Casos de Uso 2. Usa términos definidos previamente, considerando acrónimos y abreviaturas. 3. Ausencia de contradicciones entre las condiciones del flujo principal y los criterios de aceptación. | J14: OK | K14: 1. Documentación basada en modelos: Diagrama de Casos de Uso 2. Usa términos definidos previamente considerarndo acrónimos y abreviaturas. | L14: OK | M14: 1. Documentación basada en modelos: Diagrama de Casos de Uso 2. Usa términos definidos previamente, considerando acrónimos y abreviaturas. 3. Ausencia de contradicciones entre las condiciones del flujo principal y los criterios de aceptación. | N14: OK | O14: 1. Documentación basada en modelos: Diagrama de Casos de Uso 2. Usa términos definidos previamente, considerando acrónimos y abreviaturas. 3. Ausencia de contradicciones entre las condiciones del flujo principal y los criterios de aceptación. | P14: OK | Q14: 1. Documentación mediante Diagrama General de Casos de Uso (UML). 2. Ausencia de contradicciones entre las condiciones del flujo principal y los criterios de aceptación. | R14: OK | S14: 1. Documentación basada en modelos: Diagrama de Casos de Uso 2. Usa términos definidos previamente, considerando acrónimos y abreviaturas. 3. Ausencia de contradicciones entre las condiciones del flujo principal y los criterios de aceptación. | T14: OK | U14: 1. Documentación basada en modelos: Diagrama General de Casos de Uso (UML). 2. Usa términos definidos previamente en las secciones de acrónimos y catálogos (FMT-09, FMT-12). 3. Ausencia de contradicciones entre las condiciones del flujo principal y los criterios de aceptación. | V14: OK | W14: 1. Documentación mediante Diagrama General de Casos de Uso (UML). 2. Ausencia de contradicciones entre las condiciones del flujo principal y los criterios de aceptación. | X14: OK | Y14: 1. Documentación basada en modelos: Diagrama de Casos de Uso 2. Usa términos definidos previamente, considerando acrónimos y abreviaturas. 3. Ausencia de contradicciones entre las condiciones del flujo principal y los criterios de aceptación.
B15: 7 | C15: Verifiable | E15: NOK | F15: 1. Criterios de aceptación cuantificables y probables para cada requisito funcional. 2. Falta Casos de Prueba | G15: NOK | I15: 1. Requisito Medible 2. Falta Casos de Prueba | J15: NOK | K15: 1. Requisito Medible 2. Falta Casos de Prueba | L15: NOK | M15: 1. Criterios de aceptación cuantificables y probables para cada requisito funcional. 2. Falta Casos de Prueba | N15: NOK | O15: 1.El requisito es medible gracias a que cuenta con parámetros claros y Criterios de Aceptación definidos. 2. Se identifica la falta de Casos de Prueba explícitos o escenarios de validación detallados para su ejecución paso a paso. | P15: NOK | Q15: 1. Criterios de acepatción factibles. 2. Falta de Matriz de Casos de Prueba formales. | R15: NOK | S15: 1. Criterios de aceptación cuantificables y probables para cada requisito funcional. 2. Falta Casos de Prueba | T15: NOK | U15: 1. Requisito Medible a través de los Criterios de Aceptación definidos para cada reporte. 2. Falta de Matriz de Casos de Prueba formales para la ejecución y validación de datos. | V15: NOK | W15: 1. Criterios de acepatción factibles. 2. Falta de Matriz de Casos de Prueba formales. | X15: NOK | Y15: 1. Criterios de aceptación cuantificables y probables para cada requisito funcional. 2. Falta Casos de Prueba
B16: 8 | C16: Realizable | E16: NOK | F16: 1. Funcionalidad tomada en cuenta dentro de la estimación del costo del proyecto (120.42$) 2. No se ha desarrollado | G16: NOK | I16: 1. Funcionalidad tomada en cuenta dentro de la estimación del costo del proyecto (120.42$) 2. No se ha desarrollado | J16: NOK | K16: 1. Funcionalidad tomada en cuenta dentro de la estimación del costo del proyecto (120.42$) 2. No se ha desarrollado | L16: NOK | M16: 1. Funcionalidad tomada en cuenta dentro de la estimación del costo del proyecto (120.42$) 2. No se ha desarrollado | N16: NOK | O16: 1. Funcionalidad tomada en cuenta dentro de la estimación del costo del proyecto (120.42$) 2. No se ha desarrollado | P16: NOK | Q16: 1. Funcionalidad tomada en cuenta dentro de la estimación de costos ($120.42). 2. Módulo no desarrollado en código ejecutable. | R16: NOK | S16: 1. Funcionalidad tomada en cuenta dentro de la estimación del costo del proyecto (120.42$) 2. No se ha desarrollado | T16: NOK | U16: 1. Funcionalidad tomada en cuenta dentro de la estimación del costo del proyecto (120.42$) 2. No se ha desarrollado | V16: NOK | W16: 1. Funcionalidad tomada en cuenta dentro de la estimación de costos ($120.42). 2. Módulo no desarrollado en código ejecutable. | X16: NOK | Y16: 1. Funcionalidad tomada en cuenta dentro de la estimación del costo del proyecto (120.42$) 2. No se ha desarrollado
B17: 9 | C17: Traceable | E17: OK | F17: 1. Existe relación entre CU-01 y los requisitos funcionales de acceso, recuperación y cambio de contraseña. 2. Los requisitos cuentan con códigos y criterios de aceptación. | G17: OK | I17: 1. Es claro el origen del requisito y sus relaciones con otros requisitos (Se tiene los criterios de aceptacion para desarrollar la matriz de trazabilidad cliente/casos de uso y casos de uso/casos de uso) 2. Cuenta con un identificador único | J17: OK | K17: 1. CU-03 tiene relación con los requisitos funcionales de registrar, consultar, actualizar información y eliminar. 2. Los requisitos cuentan con identificadores únicos y criterios de aceptación. | L17: OK | M17: 1. Relación explícita y bidireccional entre CU-04 y sus requisitos funcionales asociados (RF-08 a RF-14) 2. Código identificador único por requisito y referencias aL formato FMT-04 | N17: OK | O17: 1.Tiene trazabilidad hacia atrás mediante la asociación explícita a su caso de uso de origen (CU-02) y su actor (Jefe TICS). 2.Cada requisito funcional cuenta con un identificador único (RF-01, RF-02, RF-03, RF-28, RF-29, RF-31). 3.Mantiene trazabilidad hacia adelante al vincular los requisitos con los riesgos del proyecto (RSK-02, RSK-03), sus criterios de aceptación y los formatos normativos (FMT-01, FMT-02, FMT-03). | P17: OK | Q17: 1. Trazabilidad bidireccional entre el caso de uso y los requisitos (RF-15 a RF-17, RF33 a RF-35). | R17: OK | S17: 1. Relación clara entre CU-07 y sus requisitos funcionales derivados (RF-22, RF-34, RF-35, RF-36 y RF-40) 2. Los requisitos cuentan con códigos y criterios de aceptación. | T17: OK | U17: 1. Es claro el origen del requisito (CU-08) y sus relaciones con el actor Jefe Financiero y los formatos FMT-09 y FMT-12. 2. Cuenta con un identificador único por cada requisito funcional (RF-23, RF-24, RF-25, RF-40) y se vincula al riesgo RSK-06. | V17: OK | W17: 1. Trazabilidad bidireccional entre el caso de uso CU-09, los códigos RF-42 a RF-46, el Módulo 7 y los riesgos RSK-02 y RSK-06. | X17: OK | Y17: 1. Relación clara entre CU-10 y sus requisitos funcionales (RF-26, RF-37, RF-38 y RF-39) 2. Los requisitos cuentan con códigos y criterios de aceptación.
B18: 10 | C18: Complete | E18: OK | F18: 1. Contiene toda la información necesaria (entradas, salidas, flujos, precondiciones, postcondiciones) para entender y diseñar la función. 2. Describe completamente la funcionalidad esperada. | G18: OK | I18: 1. Contiene toda la información necesaria (entradas, salidas, precondiciones, postcondiciones) para entender y diseñar la función. 2. Describe completamente la funcionalidad esperada. | J18: OK | K18: 1. Contiene toda la información necesaria (entradas, salidas, precondiciones, postcondiciones) para entender y diseñar la función. 2. Describe completamente la funcionalidad esperada. | L18: OK | M18: 1. Contiene toda la información necesaria (entradas, salidas, flujos, precondiciones, postcondiciones) para entender y diseñar la función. 2. Describe completamente la funcionalidad esperada. | N18: OK | O18: 1. El caso de uso abarca la totalidad del ciclo de vida de la gestión de usuarios y perfiles (creación, asignación, modificación, consulta y desactivación). 2.Describe explícitamente el flujo principal, los flujos alternativos, las excepciones y el manejo de errores para todos sus requisitos funcionales. 3.Detalla en su totalidad las entradas obligatorias, validaciones de formato, estados resultantes y salidas del sistema sin vacíos de información. | P18: OK | Q18: 1. Especifica campos de entrada, validaciones y salidas. 2. Describe completamente la funcionaliad esperada. | R18: OK | S18: 1. Contiene toda la información necesaria (entradas, salidas, flujos, precondiciones, postcondiciones) para entender y diseñar la función. 2. Describe completamente la funcionalidad esperada. | T18: OK | U18: 1. Contiene toda la información necesaria (entradas, validaciones, flujos, excepciones, salidas y criterios de aceptación) para entender y diseñar la función. 2. Describe completamente la funcionalidad esperada para el Módulo de Reportes Financieros | V18: OK | W18: 1. Especifica campos de entrada, validaciones y salidas. 2. Describe completamente la funcionaliad esperada. | X18: OK | Y18: 1. Contiene toda la información necesaria (entradas, salidas, flujos, precondiciones, postcondiciones) para entender y diseñar la función. 2. Describe completamente la funcionalidad esperada.
B19: 11 | C19: Understandability | E19: NOK | F19: 1. Se involucra al cliente 2. La información está organizada de forma estructurada. 3. Se utilizan términos definidos en el SRS. 4. No existe un glosario de términos definido | G19: NOK | I19: 1. Se involucra al cliente 3. Se utilizan términos definidos en el SRS. 4. No existe un glosario de términos definido | J19: NOK | K19: 1. Se involucra al cliente 2.La información está organizada y utiliza terminología relacionada con la gestión académica de docentes. 3. No existe un glosario de términos definido. | L19: NOK | M19: 1. Se involucra al cliente 2. La información está organizada de forma estructurada. 3. Se utilizan términos definidos en el SRS. 4. No existe un glosario de términos definido | N19: NOK | O19: 1. Se involucra al cliente 2. La información está organizada de forma estructurada. 3. Se utilizan términos definidos en el SRS. 4. No existe un glosario de términos definido | P19: NOK | Q19: 1. Contenido comprensible para el usuario. 2. Falta de Glosario de Términos. | R19: NOK | S19: 1. Se involucra al cliente 2. La información está organizada de forma estructurada. 3. Se utilizan términos definidos en el SRS. 4. No existe un glosario de términos definido | T19: NOK | U19: 1. Se involucra al cliente 2. La información está organizada de forma estructurada. 3. Se utilizan términos definidos en el SRS. 4. No existe un glosario de términos definido | V19: NOK | W19: 1. Contenido comprensible para el usuario. 2. Falta de Glosario de Términos. | X19: NOK | Y19: 1. Se involucra al cliente 2. La información está organizada de forma estructurada. 3. Se utilizan términos definidos en el SRS. 4. No existe un glosario de términos definido

Sheet MODELO LISTA DE COMPROBACION - 
B1: SISTEMA: | C1: SISTEMA DE INSCRIPCIÓN DE CURSOS (SIC)
B2: FECHA: | C2: 46296
B3: AUTOR: | C3: Andrés Cárdenas
B4: REQUERIMIENTOS EVALUADOS : | C4: CU-01 Acceder al sistema
A6: CONTENIDO
A7: No. | B7: Pregunta | C7: SI | D7: NO
A8: 1 | B8: Todos los requerimientos relevantes se han documentado? | C8: X
A9: 2 | B9: Se han implementado las funciones requeridas? | D9: X
A10: 3 | B10: Existe algún mecanismo que permita seguir el impacto de dicho requerimiento a lo largo del resto de las actividades del ciclo productivo.? | C10: X
A11: 4 | B11: El origen de cada requerimento individual está claro ? | C11: X
A12: 5 | B12: Que tan facil es devolverse a los requerimientos? | C12: X
A13: 6 | B13: Los requerimientos reflejan las necesidades y deseos del cliente? | C13: X
A14: 7 | B14: No hay contradicciones entre los requerimientos? | C14: X
A15: 8 | B15: El requerimiento que se esta especificando contribuye a alcanzar un objetivo definido ? | C15: X
A16: 9 | B16: Existe un proceso acotado (en plazo y presupuesto) que permita determinar que el sistema construido satisface lo descrito en el propio requerimiento? | D16: X
A17: SUMATORIA: | C17: =COUNTA('MODELO LISTA DE COMPROBACION - '!$C$8:$C$16) -> 7 | D17: =COUNTA('MODELO LISTA DE COMPROBACION - '!$D$8:$D$16) -> 2
A18: PORCENTAJE : | C18: =C17/9 -> 0.77777778 | D18: =D17/9 -> 0.22222222
A20: DOCUMENTACIÓN
A21: No. | B21: Pregunta | C21: SI | D21: NO
A22: 1 | B22: Aplica un estandar para la documetación de requerimiento? | C22: X
A23: 2 | B23: Cumple con la estructura definida por el estandar? | C23: X
A24: 3 | B24: Utiliza un Glosario de términos normalizado? | D24: X
A25: 4 | B25: Los requerimientos Funcionales estan sujetos a una única interpretación? | C25: X
A26: 5 | B26: El modelo aplicado cumple con la sintaxis? | C26: X
A27: SUMATORIA: | C27: =COUNTA('MODELO LISTA DE COMPROBACION - '!$C$22:$C$26) -> 4 | D27: =COUNTA('MODELO LISTA DE COMPROBACION - '!$D$22:$D$26) -> 1
A28: PORCENTAJE : | C28: =C27/5 -> 0.8 | D28: =D27/5 -> 0.2
A30: NIVEL DE ACUERDO
A31: No. | B31: Pregunta | C31: SI | D31: NO
A32: 1 | B32: Todos los requerimientos han sido acordados con todos los interesados? | C32: x
A33: 2 | B33: Todos los requerimientos modificados han sido acordados por todos los implicados? | C33: x
A34: 3 | B34: Han sido resueltos todos los conflictos conocidos respectos de los requerimientos? | C34: X
A35: SUMATORIA: | C35: =COUNTA('MODELO LISTA DE COMPROBACION - '!$C$32:$C$34) -> 3 | D35: =COUNTA('MODELO LISTA DE COMPROBACION - '!$D$32:$D$34) -> 0
A36: PORCENTAJE : | C36: =C35/3 -> 1 | D36: =D35/3 -> 0
A40: RESUMEN
B41: CONTENIDO | C41: =C18 -> 0.77777778
B42: DOCUMENTACIÓN | C42: =C28 -> 0.8
B43: NIVEL DE ACUERDO | C43: =C36 -> 1

Sheet MODELO LISTA DE COMPROBACIÓN - 
B1: SISTEMA: | C1: SISTEMA DE INSCRIPCIÓN DE CURSOS (SIC)
B2: FECHA: | C2: 46296
B3: AUTOR: | C3: Camila Bohorquez
B4: REQUERIMIENTOS EVALUADOS : | C4: CU002. Gestionar Perfiles
A6: CONTENIDO
A7: No. | B7: Pregunta | C7: SI | D7: NO
A8: 1 | B8: Todos los requerimientos relevantes se han documentado? | C8: X
A9: 2 | B9: Se han implementado las funciones requeridas? | C9: X
A10: 3 | B10: Existe algún mecanismo que permita seguir el impacto de dicho requerimiento a lo largo del resto de las actividades del ciclo productivo.? | C10: X
A11: 4 | B11: El origen de cada requerimento individual está claro ? | C11: X
A12: 5 | B12: Que tan facil es devolverse a los requerimientos? | C12: X
A13: 6 | B13: Los requerimientos reflejan las necesidades y deseos del cliente? | C13: X
A14: 7 | B14: No hay contradicciones entre los requerimientos? | D14: X
A15: 8 | B15: El requerimiento que se esta especificando contribuye a alcanzar un objetivo definido ? | C15: X
A16: 9 | B16: Existe un proceso acotado (en plazo y presupuesto) que permita determinar que el sistema construido satisface lo descrito en el propio requerimiento? | D16: X
A17: SUMATORIA: | C17: =COUNTA('MODELO LISTA DE COMPROBACIÓN - '!$C$8:$C$16) -> 7 | D17: =COUNTA('MODELO LISTA DE COMPROBACIÓN - '!$D$8:$D$16) -> 2
A18: PORCENTAJE : | C18: =C17/9 -> 0.77777778 | D18: =D17/9 -> 0.22222222
A20: DOCUMENTACIÓN
A21: No. | B21: Pregunta | C21: SI | D21: NO
A22: 1 | B22: Aplica un estandar para la documetación de requerimiento? | C22: X
A23: 2 | B23: Cumple con la estructura definida por el estandar? | C23: X
A24: 3 | B24: Utiliza un Glosario de términos normalizado? | D24: X
A25: 4 | B25: Los requerimientos Funcionales estan sujetos a una única interpretación? | C25: X
A26: 5 | B26: El modelo aplicado cumple con la sintaxis? | C26: X
A27: SUMATORIA: | C27: =COUNTA('MODELO LISTA DE COMPROBACIÓN - '!$C$22:$C$26) -> 4 | D27: =COUNTA('MODELO LISTA DE COMPROBACIÓN - '!$D$22:$D$26) -> 1
A28: PORCENTAJE : | C28: =C27/5 -> 0.8 | D28: =D27/5 -> 0.2
A30: NIVEL DE ACUERDO
A31: No. | B31: Pregunta | C31: SI | D31: NO
A32: 1 | B32: Todos los requerimientos han sido acordados con todos los interesados? | C32: x
A33: 2 | B33: Todos los requerimientos modificados han sido acordados por todos los implicados? | C33: x
A34: 3 | B34: Han sido resueltos todos los conflictos conocidos respectos de los requerimientos? | C34: X
A35: SUMATORIA: | C35: =COUNTA('MODELO LISTA DE COMPROBACIÓN - '!$C$32:$C$34) -> 3 | D35: =COUNTA('MODELO LISTA DE COMPROBACIÓN - '!$D$32:$D$34) -> 0
A36: PORCENTAJE : | C36: =C35/3 -> 1 | D36: =D35/3 -> 0
A40: RESUMEN
B41: CONTENIDO | C41: 78
B42: DOCUMENTACIÓN | C42: 80
B43: NIVEL DE ACUERDO | C43: 100

Sheet MODELO DE LISTA DE COMPROBACION
B1: SISTEMA: | C1: SISTEMA DE INSCRIPCIÓN DE CURSOS (SIC)
B2: FECHA: | C2: 46299
B3: AUTOR: | C3: Daniel Benalcázar
B4: REQUERIMIENTOS EVALUADOS : | C4: CU003 Gestionar Docentes
A6: CONTENIDO
A7: No. | B7: Pregunta | C7: SI | D7: NO
A8: 1 | B8: Todos los requerimientos relevantes se han documentado? | C8: X
A9: 2 | B9: Se han implementado las funciones requeridas? | C9: X
A10: 3 | B10: Existe algún mecanismo que permita seguir el impacto de dicho requerimiento a lo largo del resto de las actividades del ciclo productivo.? | C10: X
A11: 4 | B11: El origen de cada requerimento individual está claro ? | C11: X
A12: 5 | B12: Que tan facil es devolverse a los requerimientos? | C12: X
A13: 6 | B13: Los requerimientos reflejan las necesidades y deseos del cliente? | C13: X
A14: 7 | B14: No hay contradicciones entre los requerimientos? | D14: X
A15: 8 | B15: El requerimiento que se esta especificando contribuye a alcanzar un objetivo definido ? | C15: X
A16: 9 | B16: Existe un proceso acotado (en plazo y presupuesto) que permita determinar que el sistema construido satisface lo descrito en el propio requerimiento? | D16: X
A17: SUMATORIA: | C17: =COUNTA('MODELO DE LISTA DE COMPROBACION'!$C$8:$C$16) -> 7 | D17: =COUNTA('MODELO DE LISTA DE COMPROBACION'!$D$8:$D$16) -> 2
A18: PORCENTAJE : | C18: =C17/9 -> 0.77777778 | D18: =D17/9 -> 0.22222222
A20: DOCUMENTACIÓN
A21: No. | B21: Pregunta | C21: SI | D21: NO
A22: 1 | B22: Aplica un estandar para la documetación de requerimiento? | C22: X
A23: 2 | B23: Cumple con la estructura definida por el estandar? | C23: X
A24: 3 | B24: Utiliza un Glosario de términos normalizado? | D24: X
A25: 4 | B25: Los requerimientos Funcionales estan sujetos a una única interpretación? | C25: X
A26: 5 | B26: El modelo aplicado cumple con la sintaxis? | C26: X
A27: SUMATORIA: | C27: =COUNTA('MODELO DE LISTA DE COMPROBACION'!$C$22:$C$26) -> 4 | D27: =COUNTA('MODELO DE LISTA DE COMPROBACION'!$D$22:$D$26) -> 1
A28: PORCENTAJE : | C28: =C27/5 -> 0.8 | D28: =D27/5 -> 0.2
A30: NIVEL DE ACUERDO
A31: No. | B31: Pregunta | C31: SI | D31: NO
A32: 1 | B32: Todos los requerimientos han sido acordados con todos los interesados? | C32: x
A33: 2 | B33: Todos los requerimientos modificados han sido acordados por todos los implicados? | C33: x
A34: 3 | B34: Han sido resueltos todos los conflictos conocidos respectos de los requerimientos? | C34: X
A35: SUMATORIA: | C35: =COUNTA('MODELO DE LISTA DE COMPROBACION'!$C$32:$C$34) -> 3 | D35: =COUNTA('MODELO DE LISTA DE COMPROBACION'!$D$32:$D$34) -> 0
A36: PORCENTAJE : | C36: =C35/3 -> 1 | D36: =D35/3 -> 0
A40: RESUMEN
B41: CONTENIDO | C41: 78
B42: DOCUMENTACIÓN | C42: 80
B43: NIVEL DE ACUERDO | C43: 100

Sheet Hoja 1
B1: SISTEMA: | C1: SISTEMA DE INSCRIPCIÓN DE CURSOS (SIC)
B2: FECHA: | C2: 46306
B3: AUTOR: | C3: Andrés Cárdenas
B4: REQUERIMIENTOS EVALUADOS : | C4: CU-04: Gestionar cursos
A6: CONTENIDO
A7: No. | B7: Pregunta | C7: SI | D7: NO
A8: 1 | B8: Todos los requerimientos relevantes se han documentado? | C8: X
A9: 2 | B9: Se han implementado las funciones requeridas? | D9: X
A10: 3 | B10: Existe algún mecanismo que permita seguir el impacto de dicho requerimiento a lo largo del resto de las actividades del ciclo productivo.? | C10: X
A11: 4 | B11: El origen de cada requerimento individual está claro ? | C11: X
A12: 5 | B12: Que tan facil es devolverse a los requerimientos? | C12: X
A13: 6 | B13: Los requerimientos reflejan las necesidades y deseos del cliente? | C13: X
A14: 7 | B14: No hay contradicciones entre los requerimientos? | C14: X
A15: 8 | B15: El requerimiento que se esta especificando contribuye a alcanzar un objetivo definido ? | C15: X
A16: 9 | B16: Existe un proceso acotado (en plazo y presupuesto) que permita determinar que el sistema construido satisface lo descrito en el propio requerimiento? | D16: X
A17: SUMATORIA: | C17: =COUNTA('Hoja 1'!$C$8:$C$16) -> 7 | D17: =COUNTA('Hoja 1'!$D$8:$D$16) -> 2
A18: PORCENTAJE : | C18: =C17/9 -> 0.77777778 | D18: =D17/9 -> 0.22222222
A20: DOCUMENTACIÓN
A21: No. | B21: Pregunta | C21: SI | D21: NO
A22: 1 | B22: Aplica un estandar para la documetación de requerimiento? | C22: X
A23: 2 | B23: Cumple con la estructura definida por el estandar? | C23: X
A24: 3 | B24: Utiliza un Glosario de términos normalizado? | D24: X
A25: 4 | B25: Los requerimientos Funcionales estan sujetos a una única interpretación? | C25: X
A26: 5 | B26: El modelo aplicado cumple con la sintaxis? | C26: X
A27: SUMATORIA: | C27: =COUNTA('Hoja 1'!$C$22:$C$26) -> 4 | D27: =COUNTA('Hoja 1'!$D$22:$D$26) -> 1
A28: PORCENTAJE : | C28: =C27/5 -> 0.8 | D28: =D27/5 -> 0.2
A30: NIVEL DE ACUERDO
A31: No. | B31: Pregunta | C31: SI | D31: NO
A32: 1 | B32: Todos los requerimientos han sido acordados con todos los interesados? | C32: x
A33: 2 | B33: Todos los requerimientos modificados han sido acordados por todos los implicados? | C33: x
A34: 3 | B34: Han sido resueltos todos los conflictos conocidos respectos de los requerimientos? | C34: X
A35: SUMATORIA: | C35: =COUNTA('Hoja 1'!$C$32:$C$34) -> 3 | D35: =COUNTA('Hoja 1'!$D$32:$D$34) -> 0
A36: PORCENTAJE : | C36: =C35/3 -> 1 | D36: =D35/3 -> 0
A40: RESUMEN
B41: CONTENIDO | C41: =C18 -> 0.77777778
B42: DOCUMENTACIÓN | C42: =C28 -> 0.8
B43: NIVEL DE ACUERDO | C43: =C36 -> 1

Sheet Hoja 2
B1: SISTEMA: | C1: SISTEMA DE INSCRIPCIÓN DE CURSOS (SIC)
B2: FECHA: | C2: 46299
B3: AUTOR: | C3: Camila Bohorquez
B4: REQUERIMIENTOS EVALUADOS : | C4: CU005 Completar inscripción en línea
A6: CONTENIDO
A7: No. | B7: Pregunta | C7: SI | D7: NO
A8: 1 | B8: Todos los requerimientos relevantes se han documentado? | C8: X
A9: 2 | B9: Se han implementado las funciones requeridas? | C9: X
A10: 3 | B10: Existe algún mecanismo que permita seguir el impacto de dicho requerimiento a lo largo del resto de las actividades del ciclo productivo.? | C10: X
A11: 4 | B11: El origen de cada requerimento individual está claro ? | C11: X
A12: 5 | B12: Que tan facil es devolverse a los requerimientos? | C12: X
A13: 6 | B13: Los requerimientos reflejan las necesidades y deseos del cliente? | C13: X
A14: 7 | B14: No hay contradicciones entre los requerimientos? | D14: X
A15: 8 | B15: El requerimiento que se esta especificando contribuye a alcanzar un objetivo definido ? | C15: X
A16: 9 | B16: Existe un proceso acotado (en plazo y presupuesto) que permita determinar que el sistema construido satisface lo descrito en el propio requerimiento? | D16: X
A17: SUMATORIA: | C17: =COUNTA('Hoja 2'!$C$8:$C$16) -> 7 | D17: =COUNTA('Hoja 2'!$D$8:$D$16) -> 2
A18: PORCENTAJE : | C18: =C17/9 -> 0.77777778 | D18: =D17/9 -> 0.22222222
A20: DOCUMENTACIÓN
A21: No. | B21: Pregunta | C21: SI | D21: NO
A22: 1 | B22: Aplica un estandar para la documetación de requerimiento? | C22: X
A23: 2 | B23: Cumple con la estructura definida por el estandar? | C23: X
A24: 3 | B24: Utiliza un Glosario de términos normalizado? | D24: X
A25: 4 | B25: Los requerimientos Funcionales estan sujetos a una única interpretación? | C25: X
A26: 5 | B26: El modelo aplicado cumple con la sintaxis? | C26: X
A27: SUMATORIA: | C27: =COUNTA('Hoja 2'!$C$22:$C$26) -> 4 | D27: =COUNTA('Hoja 2'!$D$22:$D$26) -> 1
A28: PORCENTAJE : | C28: =C27/5 -> 0.8 | D28: =D27/5 -> 0.2
A30: NIVEL DE ACUERDO
A31: No. | B31: Pregunta | C31: SI | D31: NO
A32: 1 | B32: Todos los requerimientos han sido acordados con todos los interesados? | C32: x
A33: 2 | B33: Todos los requerimientos modificados han sido acordados por todos los implicados? | C33: x
A34: 3 | B34: Han sido resueltos todos los conflictos conocidos respectos de los requerimientos? | C34: X
A35: SUMATORIA: | C35: =COUNTA('Hoja 2'!$C$32:$C$34) -> 3 | D35: =COUNTA('Hoja 2'!$D$32:$D$34) -> 0
A36: PORCENTAJE : | C36: =C35/3 -> 1 | D36: =D35/3 -> 0
A40: RESUMEN
B41: CONTENIDO | C41: 78
B42: DOCUMENTACIÓN | C42: 80
B43: NIVEL DE ACUERDO | C43: 100

Sheet Hoja 3
B1: SISTEMA: | C1: SISTEMA DE INSCRIPCIÓN DE CURSOS (SIC)
B2: FECHA: | C2: 46305
B3: AUTOR: | C3: Daniel Benalcázar
B4: REQUERIMIENTOS EVALUADOS : | C4: CU006 Gestionar Becas
A6: CONTENIDO
A7: No. | B7: Pregunta | C7: SI | D7: NO
A8: 1 | B8: Todos los requerimientos relevantes se han documentado? | C8: X
A9: 2 | B9: Se han implementado las funciones requeridas? | D9: X
A10: 3 | B10: Existe algún mecanismo que permita seguir el impacto de dicho requerimiento a lo largo del resto de las actividades del ciclo productivo.? | C10: X
A11: 4 | B11: El origen de cada requerimento individual está claro ? | C11: X
A12: 5 | B12: Que tan facil es devolverse a los requerimientos? | C12: X
A13: 6 | B13: Los requerimientos reflejan las necesidades y deseos del cliente? | C13: X
A14: 7 | B14: No hay contradicciones entre los requerimientos? | C14: X
A15: 8 | B15: El requerimiento que se esta especificando contribuye a alcanzar un objetivo definido ? | C15: X
A16: 9 | B16: Existe un proceso acotado (en plazo y presupuesto) que permita determinar que el sistema construido satisface lo descrito en el propio requerimiento? | D16: X
A17: SUMATORIA: | C17: =COUNTA('Hoja 3'!$C$8:$C$16) -> 7 | D17: =COUNTA('Hoja 3'!$D$8:$D$16) -> 2
A18: PORCENTAJE : | C18: =C17/9 -> 0.77777778 | D18: =D17/9 -> 0.22222222
A20: DOCUMENTACIÓN
A21: No. | B21: Pregunta | C21: SI | D21: NO
A22: 1 | B22: Aplica un estandar para la documetación de requerimiento? | C22: X
A23: 2 | B23: Cumple con la estructura definida por el estandar? | C23: X
A24: 3 | B24: Utiliza un Glosario de términos normalizado? | D24: X
A25: 4 | B25: Los requerimientos Funcionales estan sujetos a una única interpretación? | C25: X
A26: 5 | B26: El modelo aplicado cumple con la sintaxis? | C26: X
A27: SUMATORIA: | C27: =COUNTA('Hoja 3'!$C$22:$C$26) -> 4 | D27: =COUNTA('Hoja 3'!$D$22:$D$26) -> 1
A28: PORCENTAJE : | C28: =C27/5 -> 0.8 | D28: =D27/5 -> 0.2
A30: NIVEL DE ACUERDO
A31: No. | B31: Pregunta | C31: SI | D31: NO
A32: 1 | B32: Todos los requerimientos han sido acordados con todos los interesados? | C32: x
A33: 2 | B33: Todos los requerimientos modificados han sido acordados por todos los implicados? | C33: x
A34: 3 | B34: Han sido resueltos todos los conflictos conocidos respectos de los requerimientos? | C34: X
A35: SUMATORIA: | C35: =COUNTA('Hoja 3'!$C$32:$C$34) -> 3 | D35: =COUNTA('Hoja 3'!$D$32:$D$34) -> 0
A36: PORCENTAJE : | C36: =C35/3 -> 1 | D36: =D35/3 -> 0
A40: RESUMEN
B41: CONTENIDO | C41: 78
B42: DOCUMENTACIÓN | C42: 80
B43: NIVEL DE ACUERDO | C43: 100

Sheet Hoja 4
B1: SISTEMA: | C1: SISTEMA DE INSCRIPCIÓN DE CURSOS (SIC)
B2: FECHA: | C2: 46306
B3: AUTOR: | C3: Andrés Cárdenas
B4: REQUERIMIENTOS EVALUADOS : | C4: CU-07: Consultar reportes
A6: CONTENIDO
A7: No. | B7: Pregunta | C7: SI | D7: NO
A8: 1 | B8: Todos los requerimientos relevantes se han documentado? | C8: X
A9: 2 | B9: Se han implementado las funciones requeridas? | D9: X
A10: 3 | B10: Existe algún mecanismo que permita seguir el impacto de dicho requerimiento a lo largo del resto de las actividades del ciclo productivo.? | C10: X
A11: 4 | B11: El origen de cada requerimento individual está claro ? | C11: X
A12: 5 | B12: Que tan facil es devolverse a los requerimientos? | C12: X
A13: 6 | B13: Los requerimientos reflejan las necesidades y deseos del cliente? | C13: X
A14: 7 | B14: No hay contradicciones entre los requerimientos? | C14: X
A15: 8 | B15: El requerimiento que se esta especificando contribuye a alcanzar un objetivo definido ? | C15: X
A16: 9 | B16: Existe un proceso acotado (en plazo y presupuesto) que permita determinar que el sistema construido satisface lo descrito en el propio requerimiento? | D16: X
A17: SUMATORIA: | C17: =COUNTA('Hoja 4'!$C$8:$C$16) -> 7 | D17: =COUNTA('Hoja 4'!$D$8:$D$16) -> 2
A18: PORCENTAJE : | C18: =C17/9 -> 0.77777778 | D18: =D17/9 -> 0.22222222
A20: DOCUMENTACIÓN
A21: No. | B21: Pregunta | C21: SI | D21: NO
A22: 1 | B22: Aplica un estandar para la documetación de requerimiento? | C22: X
A23: 2 | B23: Cumple con la estructura definida por el estandar? | C23: X
A24: 3 | B24: Utiliza un Glosario de términos normalizado? | D24: X
A25: 4 | B25: Los requerimientos Funcionales estan sujetos a una única interpretación? | C25: X
A26: 5 | B26: El modelo aplicado cumple con la sintaxis? | C26: X
A27: SUMATORIA: | C27: =COUNTA('Hoja 4'!$C$22:$C$26) -> 4 | D27: =COUNTA('Hoja 4'!$D$22:$D$26) -> 1
A28: PORCENTAJE : | C28: =C27/5 -> 0.8 | D28: =D27/5 -> 0.2
A30: NIVEL DE ACUERDO
A31: No. | B31: Pregunta | C31: SI | D31: NO
A32: 1 | B32: Todos los requerimientos han sido acordados con todos los interesados? | C32: x
A33: 2 | B33: Todos los requerimientos modificados han sido acordados por todos los implicados? | C33: x
A34: 3 | B34: Han sido resueltos todos los conflictos conocidos respectos de los requerimientos? | C34: X
A35: SUMATORIA: | C35: =COUNTA('Hoja 4'!$C$32:$C$34) -> 3 | D35: =COUNTA('Hoja 4'!$D$32:$D$34) -> 0
A36: PORCENTAJE : | C36: =C35/3 -> 1 | D36: =D35/3 -> 0
A40: RESUMEN
B41: CONTENIDO | C41: =C18 -> 0.77777778
B42: DOCUMENTACIÓN | C42: =C28 -> 0.8
B43: NIVEL DE ACUERDO | C43: =C36 -> 1

Sheet Hoja 5
B1: SISTEMA: | C1: SISTEMA DE INSCRIPCIÓN DE CURSOS (SIC)
B2: FECHA: | C2: 46299
B3: AUTOR: | C3: Camila Bohorquez
B4: REQUERIMIENTOS EVALUADOS : | C4: CU008 Consultar reportes financieros
A6: CONTENIDO
A7: No. | B7: Pregunta | C7: SI | D7: NO
A8: 1 | B8: Todos los requerimientos relevantes se han documentado? | C8: X
A9: 2 | B9: Se han implementado las funciones requeridas? | C9: X
A10: 3 | B10: Existe algún mecanismo que permita seguir el impacto de dicho requerimiento a lo largo del resto de las actividades del ciclo productivo.? | C10: X
A11: 4 | B11: El origen de cada requerimento individual está claro ? | C11: X
A12: 5 | B12: Que tan facil es devolverse a los requerimientos? | C12: X
A13: 6 | B13: Los requerimientos reflejan las necesidades y deseos del cliente? | C13: X
A14: 7 | B14: No hay contradicciones entre los requerimientos? | D14: X
A15: 8 | B15: El requerimiento que se esta especificando contribuye a alcanzar un objetivo definido ? | C15: X
A16: 9 | B16: Existe un proceso acotado (en plazo y presupuesto) que permita determinar que el sistema construido satisface lo descrito en el propio requerimiento? | D16: X
A17: SUMATORIA: | C17: =COUNTA('Hoja 5'!$C$8:$C$16) -> 7 | D17: =COUNTA('Hoja 5'!$D$8:$D$16) -> 2
A18: PORCENTAJE : | C18: =C17/9 -> 0.77777778 | D18: =D17/9 -> 0.22222222
A20: DOCUMENTACIÓN
A21: No. | B21: Pregunta | C21: SI | D21: NO
A22: 1 | B22: Aplica un estandar para la documetación de requerimiento? | C22: X
A23: 2 | B23: Cumple con la estructura definida por el estandar? | C23: X
A24: 3 | B24: Utiliza un Glosario de términos normalizado? | D24: X
A25: 4 | B25: Los requerimientos Funcionales estan sujetos a una única interpretación? | C25: X
A26: 5 | B26: El modelo aplicado cumple con la sintaxis? | C26: X
A27: SUMATORIA: | C27: =COUNTA('Hoja 5'!$C$22:$C$26) -> 4 | D27: =COUNTA('Hoja 5'!$D$22:$D$26) -> 1
A28: PORCENTAJE : | C28: =C27/5 -> 0.8 | D28: =D27/5 -> 0.2
A30: NIVEL DE ACUERDO
A31: No. | B31: Pregunta | C31: SI | D31: NO
A32: 1 | B32: Todos los requerimientos han sido acordados con todos los interesados? | C32: x
A33: 2 | B33: Todos los requerimientos modificados han sido acordados por todos los implicados? | C33: x
A34: 3 | B34: Han sido resueltos todos los conflictos conocidos respectos de los requerimientos? | C34: X
A35: SUMATORIA: | C35: =COUNTA('Hoja 5'!$C$32:$C$34) -> 3 | D35: =COUNTA('Hoja 5'!$D$32:$D$34) -> 0
A36: PORCENTAJE : | C36: =C35/3 -> 1 | D36: =D35/3 -> 0
A40: RESUMEN
B41: CONTENIDO | C41: 78
B42: DOCUMENTACIÓN | C42: 80
B43: NIVEL DE ACUERDO | C43: 100

Sheet Hoja 6
B1: SISTEMA: | C1: SISTEMA DE INSCRIPCIÓN DE CURSOS (SIC)
B2: FECHA: | C2: 46305
B3: AUTOR: | C3: Daniel Benalcázar
B4: REQUERIMIENTOS EVALUADOS : | C4: CU009 Gestionar auditoría
A6: CONTENIDO
A7: No. | B7: Pregunta | C7: SI | D7: NO
A8: 1 | B8: Todos los requerimientos relevantes se han documentado? | C8: X
A9: 2 | B9: Se han implementado las funciones requeridas? | D9: X
A10: 3 | B10: Existe algún mecanismo que permita seguir el impacto de dicho requerimiento a lo largo del resto de las actividades del ciclo productivo.? | C10: X
A11: 4 | B11: El origen de cada requerimento individual está claro ? | C11: X
A12: 5 | B12: Que tan facil es devolverse a los requerimientos? | C12: X
A13: 6 | B13: Los requerimientos reflejan las necesidades y deseos del cliente? | C13: X
A14: 7 | B14: No hay contradicciones entre los requerimientos? | C14: X
A15: 8 | B15: El requerimiento que se esta especificando contribuye a alcanzar un objetivo definido ? | C15: X
A16: 9 | B16: Existe un proceso acotado (en plazo y presupuesto) que permita determinar que el sistema construido satisface lo descrito en el propio requerimiento? | D16: X
A17: SUMATORIA: | C17: =COUNTA('Hoja 6'!$C$8:$C$16) -> 7 | D17: =COUNTA('Hoja 6'!$D$8:$D$16) -> 2
A18: PORCENTAJE : | C18: =C17/9 -> 0.77777778 | D18: =D17/9 -> 0.22222222
A20: DOCUMENTACIÓN
A21: No. | B21: Pregunta | C21: SI | D21: NO
A22: 1 | B22: Aplica un estandar para la documetación de requerimiento? | C22: X
A23: 2 | B23: Cumple con la estructura definida por el estandar? | C23: X
A24: 3 | B24: Utiliza un Glosario de términos normalizado? | D24: X
A25: 4 | B25: Los requerimientos Funcionales estan sujetos a una única interpretación? | C25: X
A26: 5 | B26: El modelo aplicado cumple con la sintaxis? | C26: X
A27: SUMATORIA: | C27: =COUNTA('Hoja 6'!$C$22:$C$26) -> 4 | D27: =COUNTA('Hoja 6'!$D$22:$D$26) -> 1
A28: PORCENTAJE : | C28: =C27/5 -> 0.8 | D28: =D27/5 -> 0.2
A30: NIVEL DE ACUERDO
A31: No. | B31: Pregunta | C31: SI | D31: NO
A32: 1 | B32: Todos los requerimientos han sido acordados con todos los interesados? | C32: x
A33: 2 | B33: Todos los requerimientos modificados han sido acordados por todos los implicados? | C33: x
A34: 3 | B34: Han sido resueltos todos los conflictos conocidos respectos de los requerimientos? | C34: X
A35: SUMATORIA: | C35: =COUNTA('Hoja 6'!$C$32:$C$34) -> 3 | D35: =COUNTA('Hoja 6'!$D$32:$D$34) -> 0
A36: PORCENTAJE : | C36: =C35/3 -> 1 | D36: =D35/3 -> 0
A40: RESUMEN
B41: CONTENIDO | C41: 78
B42: DOCUMENTACIÓN | C42: 80
B43: NIVEL DE ACUERDO | C43: 100

Sheet Hoja 7
B1: SISTEMA: | C1: SISTEMA DE INSCRIPCIÓN DE CURSOS (SIC)
B2: FECHA: | C2: 46306
B3: AUTOR: | C3: Andrés Cárdenas
B4: REQUERIMIENTOS EVALUADOS : | C4: CU-10: Gestionar notificaciones
A6: CONTENIDO
A7: No. | B7: Pregunta | C7: SI | D7: NO
A8: 1 | B8: Todos los requerimientos relevantes se han documentado? | C8: X
A9: 2 | B9: Se han implementado las funciones requeridas? | D9: X
A10: 3 | B10: Existe algún mecanismo que permita seguir el impacto de dicho requerimiento a lo largo del resto de las actividades del ciclo productivo.? | C10: X
A11: 4 | B11: El origen de cada requerimento individual está claro ? | C11: X
A12: 5 | B12: Que tan facil es devolverse a los requerimientos? | C12: X
A13: 6 | B13: Los requerimientos reflejan las necesidades y deseos del cliente? | C13: X
A14: 7 | B14: No hay contradicciones entre los requerimientos? | C14: X
A15: 8 | B15: El requerimiento que se esta especificando contribuye a alcanzar un objetivo definido ? | C15: X
A16: 9 | B16: Existe un proceso acotado (en plazo y presupuesto) que permita determinar que el sistema construido satisface lo descrito en el propio requerimiento? | D16: X
A17: SUMATORIA: | C17: =COUNTA('Hoja 7'!$C$8:$C$16) -> 7 | D17: =COUNTA('Hoja 7'!$D$8:$D$16) -> 2
A18: PORCENTAJE : | C18: =C17/9 -> 0.77777778 | D18: =D17/9 -> 0.22222222
A20: DOCUMENTACIÓN
A21: No. | B21: Pregunta | C21: SI | D21: NO
A22: 1 | B22: Aplica un estandar para la documetación de requerimiento? | C22: X
A23: 2 | B23: Cumple con la estructura definida por el estandar? | C23: X
A24: 3 | B24: Utiliza un Glosario de términos normalizado? | D24: X
A25: 4 | B25: Los requerimientos Funcionales estan sujetos a una única interpretación? | C25: X
A26: 5 | B26: El modelo aplicado cumple con la sintaxis? | C26: X
A27: SUMATORIA: | C27: =COUNTA('Hoja 7'!$C$22:$C$26) -> 4 | D27: =COUNTA('Hoja 7'!$D$22:$D$26) -> 1
A28: PORCENTAJE : | C28: =C27/5 -> 0.8 | D28: =D27/5 -> 0.2
A30: NIVEL DE ACUERDO
A31: No. | B31: Pregunta | C31: SI | D31: NO
A32: 1 | B32: Todos los requerimientos han sido acordados con todos los interesados? | C32: x
A33: 2 | B33: Todos los requerimientos modificados han sido acordados por todos los implicados? | C33: x
A34: 3 | B34: Han sido resueltos todos los conflictos conocidos respectos de los requerimientos? | C34: X
A35: SUMATORIA: | C35: =COUNTA('Hoja 7'!$C$32:$C$34) -> 3 | D35: =COUNTA('Hoja 7'!$D$32:$D$34) -> 0
A36: PORCENTAJE : | C36: =C35/3 -> 1 | D36: =D35/3 -> 0
A40: RESUMEN
B41: CONTENIDO | C41: =C18 -> 0.77777778
B42: DOCUMENTACIÓN | C42: =C28 -> 0.8
B43: NIVEL DE ACUERDO | C43: =C36 -> 1

Sheet RECOMENDACIONES - CU-01
A1: PREGUNTA | B1: RECOMENDACIÓN
A2: ¿Se ha incorporado los cambios sugeridos por el tutor o el cliente? | B2: Si. Se integraron las reglas solicitadas por TICS (bloqueo tras 5 intentos fallidos por 15 min y caducidad de tokens en 30 min según FMT-02 y FMT-03); se recomienda añadir una matriz de control de cambios que vincule cada observación con su versión de atención en el SRS.
A3: ¿Se mantiene la coherencia con otros requisitos del sistema y utiliza términos o definiciones de forma uniforme a lo largo del documento? | B3: Si. Mantiene consistencia con los requisitos de seguridad (RNF-08 a RNF-12) y emplea conceptos homogéneos (credenciales, sesión restringida); se recomienda consolidar estos términos en un glosario formalizado dentro del SRS.
A4: ¿Se han definido casos de prueba que permitan verificar, de manera objetiva y medible, el cumplimiento del requisito? | B4: No. Solo contiene criterios de aceptación Given-When-Then sin casos de prueba ejecutables con datos y resultados esperados; se recomienda diseñar una matriz de casos de prueba de seguridad para evaluar intentos fallidos y tokens expirados.
A5: ¿Todos los requerimientos han sido acordados con todos los interesados? | B5: Si. Se validó con el Departamento de TICS para cumplir con políticas institucionales y la Ley de Protección de Datos; se recomienda formalizar un acta de validación técnica firmada por TICS para congelar la línea base del módulo.

Sheet RECOMENDACIONES - CU-02
A1: PREGUNTA | B1: RECOMENDACIÓN
A2: ¿Se ha incorporado los cambios sugeridos por el tutor o el cliente? | B2: Sí. Se integraron las validaciones de perfiles únicos, contraseñas temporales y políticas de bloqueo ; sería recomendable incluir una matriz de control de cambios para relacionar cada observación con su ajuste en el SRS.
A3: ¿Se mantiene la coherencia con otros requisitos del sistema y utiliza términos o definiciones de forma uniforme a lo largo del documento? | B3: Sí. Mantiene consistencia con el Diagrama de Casos de Uso y la matriz de permisos ; es recomendable consolidar conceptos como "perfil activo" y "permisos efectivos" en un glosario formal dentro del SRS.
A4: ¿Se han definido criterios de aceptación y casos de prueba que permitan medir objetivamente el cumplimiento del requisito? | B4: No. Contiene criterios de aceptación (Given-When-Then), pero no especifica casos de prueba ejecutables con datos y escenarios; es recomendable elaborar una matriz de casos de prueba formales para verificar la inactivación de accesos y cierre de sesiones.
A5: ¿Todos los requerimientos han sido acordados con todos los interesados? | B5: Sí. Fue validado mediante entrevistas con el área de TICS y reuniones de consenso; es recomendable suscribir un acta de aprobación formal firmada por TICS para congelar la línea base del módulo.

Sheet RECOMENDACIONES - CU-03
A1: PREGUNTA | B1: RECOMENDACIÓN
A2: ¿Se ha incorporado los cambios sugeridos por el tutor o el cliente? | B2: Se recomienda incorporar al inicio del documento una Tabla de Control de Versiones (número de versión, fecha, autor y descripción del cambio) y adjuntar una Matriz de Atención a Observaciones donde se clasifique cada comentario del tutor/cliente (ID de observación, descripción, estado: Incorporada / Justificada / Rechazada, y sección o requisito del SRS modificado).
A3: ¿Se mantiene la coherencia con otros requisitos del sistema y utiliza términos o definiciones de forma uniforme a lo largo del documento? | B3: El CU-03 mantiene coherencia con los requisitos funcionales establecidos, sin embargo, se recomienda integrar un glosario de términos para mantener la misma definición de términos en el documento.
A4: ¿Se han definido casos de prueba que permitan verificar, de manera objetiva y medible, el cumplimiento del requisito? | B4: Se recomienda elaborar una matriz de casos de prueba derivada directamente de los criterios de aceptación y flujos alternativos documentados en el SR, asegurando la trazabilidad bidireccional entre cada requisito (RF/RNF) y sus respectivos casos de prueba unitarios, de integración y de sistema.
A5: ¿Todos los requerimientos han sido acordados con todos los interesados? | B5: Se recomienda formalizar una fase de revisión y validación conjunta con todos los actores identificados, incorporar un acta o sección de aprobación formal y cerrar las reglas de negocio pendientes antes de congelar la línea base del alcance.

Sheet RECOMENDACIONES - CU-04
A1: PREGUNTA | B1: RECOMENDACIÓN
A2: ¿Se ha incorporado los cambios sugeridos por el tutor o el cliente? | B2: Si. Se incluyó el mínimo de 10 inscritos, modalidades y causales de reprogramación pedidas por la Jefa Académica; se recomienda incorporar una tabla de control de versiones por módulo para registrar estas modificaciones operativas.
A3: ¿Se mantiene la coherencia con otros requisitos del sistema y utiliza términos o definiciones de forma uniforme a lo largo del documento? | B3: Si. Guarda coherencia con los estados del curso (FMT-04) y los datos docentes (FMT-05); se recomienda adjuntar un diagrama de máquina de estados UML para asegurar las transiciones válidas del curso.
A4: ¿Se han definido casos de prueba que permitan verificar, de manera objetiva y medible, el cumplimiento del requisito? | B4: No. Posee criterios de aceptación medibles pero carece de casos de prueba formales; se recomienda elaborar casos de prueba funcionales con análisis de valores límite (ej. 9, 10 y 11 inscritos) y cruces de horarios.
A5: ¿Todos los requerimientos han sido acordados con todos los interesados? | B5: Si. Fueron consensuados directamente con la Jefa Académica durante las entrevistas presenciales; se recomienda formalizar un acta de aprobación del alcance académico con la Dirección y Jefatura Académica.

Sheet RECOMENDACIONES - CU-05
A1: PREGUNTA | B1: RECOMENDACIÓN
A2: ¿Se ha incorporado los cambios sugeridos por el tutor o el cliente? | B2: Sí. Se incluyó el control de cupos, la validación de archivos de 5 MB , el comprobante en PDF y la separación de estados ; es recomendable adjuntar los prototipos no funcionales (wireframes) aprobados por el cliente.
A3: ¿Se mantiene la coherencia con otros requisitos del sistema y utiliza términos o definiciones de forma uniforme a lo largo del documento? | B3: Sí. Existe coherencia con los formatos FMT-03, FMT-09, FMT-10 y FMT-11; es recomendable unificar en el glosario la diferencia entre "comprobante de pago" y "comprobante de inscripción".
A4: ¿Se han definido criterios de aceptación y casos de prueba que permitan medir objetivamente el cumplimiento del requisito? | B4: No. Presenta criterios de aceptación cuantificables, pero carece de casos de prueba formales; sería recomendable estructurar casos de prueba de integración que evalúen inscripciones duplicadas, malware y concurrencia de cupos.
A5: ¿Todos los requerimientos han sido acordados con todos los interesados? | B5: Sí. Se validó con la Jefa Académica y TICS en sesiones de levantamiento; es recomendable formalizar el acta de conformidad final para cerrar la especificación del flujo de inscripción.

Sheet RECOMENDACIONES - CU-06
A1: PREGUNTA | B1: RECOMENDACIÓN
A2: ¿Se ha incorporado los cambios sugeridos por el tutor o el cliente? | B2: Se recomienda incorporar al inicio del documento una Tabla de Control de Versiones (número de versión, fecha, autor y descripción del cambio) y adjuntar una Matriz de Atención a Observaciones donde se clasifique cada comentario del tutor/cliente (ID de observación, descripción, estado: Incorporada / Justificada / Rechazada, y sección o requisito del SRS modificado).
A3: ¿Se mantiene la coherencia con otros requisitos del sistema y utiliza términos o definiciones de forma uniforme a lo largo del documento? | B3: El CU-06 mantiene coherencia con los requisitos funcionales establecidos, sin embargo, se recomienda integrar un glosario de términos para mantener la misma definición de términos en el documento.
A4: ¿Se han definido casos de prueba que permitan verificar, de manera objetiva y medible, el cumplimiento del requisito? | B4: Elaborar una Matriz de Casos de Prueba derivada de los Criterios de Aceptación (en formato Given-When-Then) que permita validar objetivamente la carga del CSV, verificando la aceptación de coberturas válidas (50% y 100%) y el rechazo automático de registros duplicados o corruptos.
A5: ¿Todos los requerimientos han sido acordados con todos los interesados? | B5: Formalizar una fase de revisión y validación conjunta con todos los actores (Jefa Académica, Dirección y Financiero), adjuntando un Acta de Aprobación Formal firmada antes de congelar la línea base del alcance.

Sheet RECOMENDACIONES - CU-07
A1: PREGUNTA | B1: RECOMENDACIÓN
A2: ¿Se ha incorporado los cambios sugeridos por el tutor o el cliente? | B2: Si. Se crearon reportes centralizados de inscritos y beneficiarios de beca (100 %) y media beca (50 %) requeridos por la Jefa Académica; se recomienda adjuntar prototipos no funcionales (wireframes) para validar la disposición visual de las columnas.
A3: ¿Se mantiene la coherencia con otros requisitos del sistema y utiliza términos o definiciones de forma uniforme a lo largo del documento? | B3: Si. Se articula con los estados de inscripción (FMT-09) y el catálogo de reportes (FMT-12); se recomienda normalizar en el glosario las definiciones y fórmulas exactas de las métricas reportadas.
A4: ¿Se han definido casos de prueba que permitan verificar, de manera objetiva y medible, el cumplimiento del requisito? | B4: No. Los criterios de aceptación no sustituyen casos de prueba formales ante filtros vacíos o combinados; se recomienda estructurar casos de prueba de integración que evalúen el rendimiento con distintos volúmenes de datos.
A5: ¿Todos los requerimientos han sido acordados con todos los interesados? | B5: Si. Fueron validados con la Jefa Académica para atender la supervisión institucional; se recomienda definir una matriz de permisos de visualización que delimite qué perfiles pueden exportar información sensible.

Sheet RECOMENDACIONES - CU-08
A1: PREGUNTA | B1: RECOMENDACIÓN
A2: ¿Se ha incorporado los cambios sugeridos por el tutor o el cliente? | B2: Sí. Se estructuraron las consultas de pagos registrados, pendientes, consolidados por curso y filtros combinados (RF-23, RF-24, RF-25, RF-40); es reocmendable incluir una tabla de trazabilidad de cambios para auditar el ajuste de estas funciones.
A3: ¿Se mantiene la coherencia con otros requisitos del sistema y utiliza términos o definiciones de forma uniforme a lo largo del documento? | B3: Sí. Mantiene alineación con los estados de pago (FMT-09) y las fórmulas del catálogo de reportes (FMT-12); es recomendable definir formalmente en un anexo las fórmulas de "saldo pendiente" y "monto validado".
A4: ¿Se han definido criterios de aceptación y casos de prueba que permitan medir objetivamente el cumplimiento del requisito? | B4: No. Incluye criterios de aceptación medibles, pero no contiene casos de prueba ejecutables; sería recomendable diseñar una matriz de casos de prueba financieros para validar la exactitud de los cálculos y filtros.
A5: ¿Todos los requerimientos han sido acordados con todos los interesados? | B5: Sí. Fue concertado con el Jefe Financiero y el departamento de TICS; es recomendable suscribir el acta de aprobación firmada por la Jefatura Financiera para validar la estructura de las métricas.

Sheet RECOMENDACIONES - CU-09
A1: PREGUNTA | B1: RECOMENDACIÓN
A2: ¿Se ha incorporado los cambios sugeridos por el tutor o el cliente? | B2: Incorporar al inicio del SRS una Tabla de Control de Versiones (versión, fecha, autor y descripción del cambio) y adjuntar una Matriz de Atención a Observaciones donde se clasifique cada comentario del tutor o cliente (ID de observación, descripción, estado: Incorporada / Justificada / Rechazada y sección/RF modificado)
A3: ¿Se mantiene la coherencia con otros requisitos del sistema y utiliza términos o definiciones de forma uniforme a lo largo del documento? | B3: Integrar en el SRS la definición explícita y uniforme de términos técnicos de auditoría como: Evento Auditable, Inmutabilidad, Hash de Integridad, Valores Previo y Posterior y Bitácora de Sistema.
